[DEBUG] MCP server main() started
[DEBUG] Waiting for input...
Traceback (most recent call last):
  File "/opt/homebrew/Cellar/python@3.11/3.11.13/Frameworks/Python.framework/Versions/3.11/lib/python3.11/asyncio/runners.py", line 118, in run
    return self._loop.run_until_complete(task)
           ^^^^^^^^^^^^^^^^^^^^^^^^^^^^^^^^^^^
  File "/opt/homebrew/Cellar/python@3.11/3.11.13/Frameworks/Python.framework/Versions/3.11/lib/python3.11/asyncio/base_events.py", line 654, in run_until_complete
    return future.result()
           ^^^^^^^^^^^^^^^
  File "/Users/georgiigavrilenko/Documents/GitHub/pyHaasAPI/tools/mcp/unified_mcp_server.py", line 423, in main
    line = await asyncio.get_event_loop().run_in_executor(None, sys.stdin.readline)
           ^^^^^^^^^^^^^^^^^^^^^^^^^^^^^^^^^^^^^^^^^^^^^^^^^^^^^^^^^^^^^^^^^^^^^^^^
asyncio.exceptions.CancelledError

During handling of the above exception, another exception occurred:

Traceback (most recent call last):
  File "/Users/georgiigavrilenko/Documents/GitHub/pyHaasAPI/tools/mcp/unified_mcp_server.py", line 440, in <module>
    asyncio.run(main()) 
    ^^^^^^^^^^^^^^^^^^^
  File "/opt/homebrew/Cellar/python@3.11/3.11.13/Frameworks/Python.framework/Versions/3.11/lib/python3.11/asyncio/runners.py", line 190, in run
    return runner.run(main)
           ^^^^^^^^^^^^^^^^
  File "/opt/homebrew/Cellar/python@3.11/3.11.13/Frameworks/Python.framework/Versions/3.11/lib/python3.11/asyncio/runners.py", line 123, in run
    raise KeyboardInterrupt()
KeyboardInterrupt
